<?xml version="1.0"?>
<robot name="lolo_auv">

  <link name="base_link">
    <visual>
      <!--This is the INS' reference point.-->
      <origin xyz="0 0 0" rpy="0 0 0"/>
      <geometry>
        <mesh filename="mesh/lolo_hull.dae" scale="1 1 1" />
      </geometry>
    </visual>
  </link>

  <link name="dvl_link"/>
  <link name="fls_link"/>
  <link name="gps_link"/>
  <link name="mbes_link"/>
  <link name="usbl_link"/>
  <link name="camera_link"/>
  
  <!-- Hydrostatic links.-->
  <link name="buoyancy_center_link"/>
  <link name="gravity_center_link"/>

  <link name="elevator">
    <visual>
      <origin xyz="0 0 0" rpy="0 0 0" />
      <geometry>
        <mesh filename="mesh/lolo_elevator.dae" scale="1 1 1"/>
      </geometry>
    </visual>
  </link>

  <link name="rudder_stbd">
    <visual>
      <origin xyz="0 0 0" rpy="0 0 0" />
      <geometry>
        <mesh filename="mesh/lolo_rudder.dae" scale="1 1 1"/>
      </geometry>
    </visual>
  </link>

  <link name="rudder_port">
    <visual>
      <origin xyz="0 0 0" rpy="0 0 0" />
      <geometry>
        <mesh filename="mesh/lolo_rudder.dae" scale="1 1 1"/>
      </geometry>
    </visual>
  </link>

  <link name="elevon_stbd">
    <visual>
      <origin xyz="0 0 0" rpy="0 0 0" />
      <geometry>
        <mesh filename="mesh/lolo_stbd_elevon.dae" scale="1 1 1"/>
      </geometry>
    </visual>
  </link>

  <link name="elevon_port">
    <visual>
      <origin xyz="0 0 0" rpy="0 0 0" />
      <geometry>
        <mesh filename="mesh/lolo_port_elevon.dae" scale="1 1 1"/>
      </geometry>
    </visual>
  </link>

  <link name="thruster_port">
    <visual>
      <origin xyz="0.0 0 0" rpy="0 0 0" />
      <geometry>
        <mesh filename="mesh/lolo_port_propeller.dae" scale="1 1 1"/>
      </geometry>
    </visual>
  </link>

  <link name="thruster_stbd">
    <visual>
      <origin xyz="0.0 0 0" rpy="0 0 0" />
      <geometry>
        <mesh filename="mesh/lolo_stbd_propeller.dae" scale="1 1 1"/>
      </geometry>
    </visual>
  </link>
  
  <!-- vertical thruster links -->

  <link name="vert_thruster_front_stbd">
	<visual>
      <origin xyz="0 0 0" rpy="0 0 0" />
      <geometry>
        <mesh filename="mesh/lolo_vert_thruster.dae" scale="1 1 1"/>
      </geometry>
    </visual>
  </link>
  
  <link name="vert_thruster_front_port">
	<visual>
      <origin xyz="0 0 0" rpy="0 0 0" />
      <geometry>
        <mesh filename="mesh/lolo_vert_thruster.dae" scale="1 1 1"/>
      </geometry>
    </visual>
  </link>
  
  <link name="vert_thruster_back_stbd">
	<visual>
      <origin xyz="0 0 0" rpy="0 0 0" />
      <geometry>
        <mesh filename="mesh/lolo_vert_thruster.dae" scale="1 1 1"/>
      </geometry>
    </visual>
  </link>
  
  <link name="vert_thruster_back_port">
	<visual>
      <origin xyz="0 0 0" rpy="0 0 0" />
      <geometry>
        <mesh filename="mesh/lolo_vert_thruster.dae" scale="1 1 1"/>
      </geometry>
    </visual>
  </link>

  <!-- joints -->
  <!-- control surfaces -->
  <joint name="elevator_joint" type="revolute">
    <origin xyz="-1.265 0 0.203" rpy="0 0 0" />
    <parent link="base_link" />
    <child link="elevator" />
    <limit effort="0" lower="-0.7853" upper="0.7853" velocity="0"/>
    <axis xyz="0 1 0"/>
  </joint>

  <joint name="rudder_stbd_joint" type="revolute">
    <origin xyz="-0.945 -0.252 0.287" rpy="0 0 0" />
    <parent link="base_link" />
    <child link="rudder_stbd" />
    <limit effort="0" lower="-0.7853" upper="0.7853" velocity="0"/>
    <axis xyz="0 0 1"/>
  </joint>

  <joint name="rudder_port_joint" type="revolute">
    <origin xyz="-0.945 0.252 0.287" rpy="0 0 0" />
    <parent link="base_link" />
    <child link="rudder_port" />
    <limit effort="0" lower="-0.7853" upper="0.7853" velocity="0"/>
    <axis xyz="0 0 1"/>
  </joint>

  <joint name="elevon_stbd_joint" type="revolute">
    <origin xyz="-1.04 -0.509 0.204" rpy="0 0 0" />
    <parent link="base_link" />
    <child link="elevon_stbd" />
    <limit effort="0" lower="-0.7853" upper="0.7853" velocity="0"/>
    <axis xyz="0 1 0"/>
  </joint>

  <joint name="elevon_port_joint" type="revolute">
    <origin xyz="-1.04 0.509 0.204" rpy="0 0 0" />
    <parent link="base_link" />
    <child link="elevon_port" />
    <limit effort="0" lower="-0.7853" upper="0.7853" velocity="0"/>
    <axis xyz="0 1 0"/>
  </joint>

  <!-- thrusters -->
  <joint name="thruster_stbd_joint" type="continuous">
    <origin xyz="-1.551 -0.277 0.204" rpy="0 0 0" />
    <axis xyz="1 0 0"/>
    <parent link="base_link"/>
    <child link="thruster_stbd"/>
  </joint>

  <joint name="thruster_port_joint" type="continuous">
    <origin xyz="-1.551 0.277 0.204" rpy="0 0 0" />
    <axis xyz="1 0 0"/>
    <parent link="base_link"/>
    <child link="thruster_port"/>
  </joint>

  <!-- vertical thrusters -->
  <joint name="vert_thruster_front_stbd_joint" type="continuous">
    <origin xyz="1.875 -0.381 0.241" rpy="0 0 0" />
    <axis xyz="0 0 1"/>
    <parent link="base_link"/>
    <child link="vert_thruster_front_stbd"/>
  </joint>

  <joint name="vert_thruster_front_port_joint" type="continuous">
    <origin xyz="1.875 0.381 0.241" rpy="0 0 0" />
    <axis xyz="0 0 1"/>
    <parent link="base_link"/>
    <child link="vert_thruster_front_port"/>
  </joint>

  <joint name="vert_thruster_back_stbd_joint" type="continuous">
    <origin xyz="-1.083 -0.102 0.193" rpy="0 0 0" />
    <axis xyz="0 0 1"/>
    <parent link="base_link"/>
    <child link="vert_thruster_back_stbd"/>
  </joint>

  <joint name="vert_thruster_back_port_joint" type="continuous">
    <origin xyz="-1.083 0.102 0.193" rpy="0 0 0" />
    <axis xyz="0 0 1"/>
    <parent link="base_link"/>
    <child link="vert_thruster_back_port"/>
  </joint>

  <!-- sensors -->
  <joint name="dvl_joint" type="fixed">
    <origin xyz="0.241 0.0025 0.007" rpy="0 0 0" />
    <parent link="base_link"/>
    <child link="dvl_link"/>
  </joint>

  <joint name="fls_joint" type="fixed">
    <origin xyz="2.263 -0.03 0.17" rpy="0 0.284 0" />
    <parent link="base_link"/>
    <child link="fls_link"/>
  </joint>

  <joint name="gps_joint" type="fixed">
    <origin xyz="-0.308 0.002 0.659" rpy="0 0 0" />
    <parent link="base_link"/>
    <child link="gps_link"/>
  </joint>

  <!--Norbit MBES-->
  <joint name="mbes_joint" type="fixed">
    <origin xyz="-0.753 0.0 0.088" rpy="3.14159 1.53589 0" />
    <parent link="base_link"/>
    <child link="mbes_link"/>
  </joint>

  <joint name="usbl_joint" type="fixed">
    <origin xyz="1.611 0.097 0.481" rpy="0 0 0" />
    <parent link="base_link"/>
    <child link="usbl_link"/>
  </joint>

  <joint name="camera_joint" type="fixed">
    <origin xyz="-0.6561 0.003 0.4935" rpy="-1.5707 0 1.5707" />
    <parent link="base_link"/>
    <child link="camera_link"/>
  </joint>

  <!-- Hydrostatic joints.-->
  <joint name="gravity_center_joint" type="fixed">
    <origin xyz="0.598 0.0 0.168" rpy="0 0 0" />
    <parent link="base_link"/>
    <child link="gravity_center_link"/>
  </joint>

  <joint name="buoyancy_center_joint" type="fixed">
    <origin xyz="0.61 0.0 0.232" rpy="0 0 0" />
    <parent link="base_link"/>
    <child link="buoyancy_center_link"/>
  </joint>


</robot>